<robot xmlns:xacro="http://www.ros.org/wiki/xacro">

    <xacro:macro name="swerve2_drive"
                 params="prefix x_offset y_offset z_offset  connected_to">

        <link name="${prefix}_pivot">
            <visual>
                <origin xyz="0 0 0" rpy="0 0 0"/>
                <geometry>
                    <mesh filename="package://rc_description/meshes/common/swerve2_pivot.stl"
                          scale="1 1 1"/>
                </geometry>
            </visual>
            <inertial>
                <mass value="0.39424"/>
                <origin xyz="0.01425 0.05517 -0.04392" rpy="0 0 0"/>
                <inertia ixx="0.00198992249" ixy="0.00017514301" ixz="0.00002829715" iyy="0.00128125084" iyz="0.00009365983"
                         izz="0.001914796"/>
            </inertial>
        </link>

        <joint name="${prefix}_pivot_joint" type="revolute">
            <axis xyz="0 0 1"/>
            <origin xyz="${x_offset} ${y_offset} ${z_offset}" rpy="0 0 0"/>
            <parent link="${connected_to}"/>
            <child link="${prefix}_pivot"/>
            <dynamics damping="0.0" friction="0.5"/>
            <limit effort="1.2" velocity="50" lower="-1e10" upper="1e10"/>
        </joint>


        <link name="${prefix}_wheel">
            <visual>
                <origin xyz="0 0 0" rpy="0 0 -0.174"/>
                <geometry>
                    <mesh filename="package://rc_description/meshes/common/swerve2_wheel.stl"
                          scale="1 1 1"/>
                </geometry>
            </visual>
            <inertial>
                <mass value="0.54132"/>
                <origin xyz="0.00323 0.00278 -0.00098" rpy="0 0 0"/>
                <inertia ixx="0.00061372726" ixy="-0.00010012016" ixz="-0.00000384326" iyy="0.00058090699" iyz="-0.00000258411"
                         izz="0.00048993818"/>
            </inertial>
            <collision>
                <origin xyz="0 0 0" rpy="${pi/2.} 0 0"/>
                <geometry>
                    <cylinder length="0.036" radius="0.054"/>
                </geometry>
            </collision>
        </link>

        <joint name="${prefix}_wheel_joint" type="revolute">
            <axis xyz="0 1 0"/>
            <origin xyz="0 0 -0.06635" rpy="0 0 0"/>
            <parent link="${prefix}_pivot"/>
            <child link="${prefix}_wheel"/>
            <limit effort="3" velocity="76" lower="-1e10" upper="1e10"/>
            <dynamics damping="0.0" friction="0.05"/>
        </joint>

        <gazebo reference="${prefix}_wheel">
            <mu1 value="1.0"/>
            <mu2 value="1.0"/>
            <kp value="1000000.0"/>
            <kd value="100.0"/>
            <material>Gazebo/Black</material>
        </gazebo>
    </xacro:macro>

    <xacro:macro name="swerve_transmission" params="prefix wheel_reduction  pivot_offset">

        <transmission name="${prefix}_pivot_trans">
            <type>transmission_interface/SimpleTransmission</type>
            <actuator name="${prefix}_pivot_motor">
                <mechanicalReduction>-1</mechanicalReduction>
            </actuator>
            <joint name="${prefix}_pivot_joint">
                <offset>${pivot_offset}</offset>
                <hardwareInterface>hardware_interface/EffortJointInterface</hardwareInterface>
            </joint>
        </transmission>

        <transmission name="${prefix}_wheel_trans">
            <type>transmission_interface/SimpleTransmission</type>
            <actuator name="${prefix}_wheel_motor">
                <mechanicalReduction>${wheel_reduction}</mechanicalReduction>
            </actuator>
            <joint name="${prefix}_wheel_joint">
                <hardwareInterface>hardware_interface/EffortJointInterface</hardwareInterface>
            </joint>
        </transmission>
    </xacro:macro>

</robot>
